<?xml version="1.0"?>
<robot name="right_schunk_hand">
    <link name="right_hand_base">
      <visual>
        <origin xyz="0 0 -0.032" rpy="0 0 0" />
        <geometry>
          <mesh filename="package://meshes/schunk_right/base10.dae" />
        </geometry>
      </visual>
      <collision>
        <origin xyz="0 0 -0.032" rpy="0 0 0" />
        <geometry>
          <mesh filename="package://meshes/schunk_right/base10.dae" />
        </geometry>
      </collision>
    </link>

    <link name="Rd">
      <!-- <visual> -->
      <!--      <geometry> -->
      <!--        <cylinder length="0.110" radius="${cyl_radius}" /> -->
      <!--      </geometry> -->
      <!--      <material name="${name}_green" /> -->
      <!-- </visual> -->
    </link>

    <link name="Rh">
      <!-- <visual> -->
      <!--      <origin rpy="0 1.571 0" xyz="${side*(-0.0125)} 0 0.0825" /> -->
      <!--      <geometry> -->
      <!--        <cylinder length="0.025" radius="${cyl_radius}" /> -->
      <!--      </geometry> -->
      <!--      <material name="${name}_green" /> -->
      <!-- </visual> -->
    </link>

    <link name="Rd2">
      <!-- <visual> -->
      <!--      <origin rpy="0 0 0" xyz="${side*(-0.025)} 0 0.09625" /> -->
      <!--      <geometry> -->
      <!--        <cylinder length="0.0275" radius="${cyl_radius}" /> -->
      <!--      </geometry> -->
      <!--      <material name="${name}_green" /> -->
      <!-- </visual> -->
    </link>

    <link name="Re1">
      <visual>
        <origin rpy="0 0 0" xyz="0 0.01313 0" />
        <geometry>
          <mesh scale="1 1 1" filename="package://meshes/schunk_right/h10.dae" />
        </geometry>
      </visual>
      <collision>
        <origin rpy="0 0 0" xyz="0 0.01313 0" />
        <geometry>
          <mesh scale="1 1 1" filename="package://meshes/schunk_right/h10.dae" />
        </geometry>
      </collision>
    </link>

    <link name="Re2">
      <visual>
        <origin xyz="-0.0007 0 -0.01002" />
        <geometry>
          <mesh scale="1 1 1" filename="package://meshes/schunk_right/h11.dae" />
        </geometry>
      </visual>
      <collision>
        <origin xyz="-0.0007 0 -0.01002" />
        <geometry>
          <mesh scale="1 1 1" filename="package://meshes/schunk_right/h11.dae" />
        </geometry>
      </collision>
    </link>

    <!-- LENGTH NOT FOUND IN DATASHEET! GUESSED!!! -->
    <link name="Re3">
      <!-- <visual> -->
      <!--      <origin rpy="0 0 0" xyz="${side*(0.0175)} 0 0.015" /> -->
      <!--      <geometry> -->
      <!--        <cylinder length="0.03" radius="${cyl_radius}" /> -->
      <!--      </geometry> -->
      <!--      <material name="green" /> -->
      <!-- </visual> -->
    </link>

    <link name="Re">
    </link>

    <!-- LENGTH NOT FOUND IN DATASHEET! GUESSED, BUT POSITION CALCULATED: E4 = D-G-F!!! -->
    <link name="Re4">
      <!-- <visual> -->
      <!--      <origin rpy="0 0 0" xyz="${side*(0.02825)} 0 0.043" /> -->
      <!--      <geometry> -->
      <!--        <cylinder length="0.026" radius="${cyl_radius}" /> -->
      <!--      </geometry> -->
      <!--      <material name="green" /> -->
      <!-- </visual> -->
    </link>

    <!-- LENGTH NOT FOUND IN DATASHEET! GUESSED, BUT POSITION CALCULATED: E5 = D-G!!! -->
    <link name="Re5">
      <!-- <visual> -->
      <!--      <origin rpy="0 0 0" xyz="${side*(0.00675)} 0 0.04775" /> -->
      <!--      <geometry> -->
      <!--        <cylinder length="0.0355" radius="${cyl_radius}" /> -->
      <!--      </geometry> -->
      <!--      <material name="green" /> -->
      <!-- </visual> -->
    </link>


  <!-- THUMB LINKS -->
    <link name="Rthumb_1">
      <visual>
        <origin xyz="0 0 0.02442" />
        <geometry>
          <mesh scale="1 1 1" filename="package://meshes/schunk_right/d10.dae" />
        </geometry>
      </visual>
      <collision>
        <origin xyz="0 0 0.02442" />
        <geometry>
          <mesh scale="1 1 1" filename="package://meshes/schunk_right/d10.dae" />
        </geometry>
      </collision>
    </link>
    <link name="Rthumb_virtual_2">
    </link>
    <link name="Rthumb_3">
      <visual>
        <geometry>
          <mesh scale="1 1 1" filename="package://meshes/schunk_right/d11.dae" />
        </geometry>
      </visual>
      <collision>
        <geometry>
          <mesh scale="1 1 1" filename="package://meshes/schunk_right/d11.dae" />
        </geometry>
      </collision>
    </link>
    <link name="Rthumb_4">
      <visual>
        <geometry>
          <mesh scale="1 1 1" filename="package://meshes/schunk_right/d12.dae" />
        </geometry>
      </visual>
      <collision>
        <geometry>
          <mesh scale="1 1 1" filename="package://meshes/schunk_right/d12.dae" />
        </geometry>
      </collision>
    </link>
    <link name="Rthumb_5">
      <visual>
        <geometry>
          <mesh scale="1 1 1" filename="package://meshes/schunk_right/d13.dae" />
        </geometry>
      </visual>
      <collision>
        <geometry>
          <mesh scale="1 1 1" filename="package://meshes/schunk_right/d13.dae" />
        </geometry>
      </collision>
    </link>


  <!-- INDEX FINGER LINKS -->
    <link name="Rvirtual_index_1">
      <visual>
        <origin xyz="0 0 0.01321" />
        <geometry>
          <mesh filename="package://meshes/schunk_right/f10.dae" />
        </geometry>
      </visual>
      <collision>
        <origin xyz="0 0 0.01321" />
        <geometry>
          <mesh filename="package://meshes/schunk_right/f10.dae" />
        </geometry>
      </collision>
    </link>
    <link name="Rindex_2">
      <visual>
        <geometry>
          <mesh filename="package://meshes/schunk_right/f11.dae" />
        </geometry>
      </visual>
      <collision>
        <geometry>
          <mesh filename="package://meshes/schunk_right/f11.dae" />
        </geometry>
      </collision>
    </link>
    <link name="Rindex_3">
      <visual>
        <geometry>
          <mesh filename="package://meshes/schunk_right/f12.dae" />
        </geometry>
      </visual>
      <collision>
        <geometry>
          <mesh filename="package://meshes/schunk_right/f12.dae" />
        </geometry>
      </collision>
    </link>
    <link name="Rindex_4">
      <visual>
        <geometry>
          <mesh filename="package://meshes/schunk_right/f13.dae" />
        </geometry>
      </visual>
      <collision>
        <geometry>
          <mesh filename="package://meshes/schunk_right/f13.dae" />
        </geometry>
      </collision>
    </link>

  <!-- MIDDLE FINGER LINKS -->
    <link name="Rvirtual_middle_1">
      <visual>
        <origin xyz="0 0 0.01321" />
        <geometry>
          <mesh filename="package://meshes/schunk_right/f20.dae" />
        </geometry>
      </visual>
      <collision>
        <origin xyz="0 0 0.01321" />
        <geometry>
          <mesh filename="package://meshes/schunk_right/f20.dae" />
        </geometry>
      </collision>
    </link>
    <link name="Rmiddle_2">
      <visual>
        <geometry>
          <mesh filename="package://meshes/schunk_right/f21.dae" />
        </geometry>
      </visual>
      <collision>
        <geometry>
          <mesh filename="package://meshes/schunk_right/f21.dae" />
        </geometry>
      </collision>
    </link>
    <link name="Rmiddle_3">
      <visual>
        <geometry>
          <mesh filename="package://meshes/schunk_right/f22.dae" />
        </geometry>
      </visual>
      <collision>
        <geometry>
          <mesh filename="package://meshes/schunk_right/f22.dae" />
        </geometry>
      </collision>
    </link>
    <link name="Rmiddle_4">
      <visual>
        <geometry>
          <mesh filename="package://meshes/schunk_right/f23.dae" />
        </geometry>
      </visual>
      <collision>
        <geometry>
          <mesh filename="package://meshes/schunk_right/f23.dae" />
        </geometry>
      </collision>
    </link>


  <!-- RING FINGER LINKS -->
    <link name="Rvirtual_ring_1">
      <visual>
        <origin xyz="0 0 -0.01321" />
        <geometry>
          <mesh filename="package://meshes/schunk_right/f30.dae" />
        </geometry>
      </visual>
      <collision>
        <origin xyz="0 0 -0.01321" />
        <geometry>
          <mesh filename="package://meshes/schunk_right/f30.dae" />
        </geometry>
      </collision>
    </link>
    <link name="Rring_2">
      <visual>
        <geometry>
          <mesh filename="package://meshes/schunk_right/f31.dae" />
        </geometry>
      </visual>
      <collision>
        <geometry>
          <mesh filename="package://meshes/schunk_right/f31.dae" />
        </geometry>
      </collision>
    </link>
    <link name="Rring_3">
      <visual>
        <geometry>
          <mesh filename="package://meshes/schunk_right/f32.dae" />
        </geometry>
      </visual>
      <collision>
        <geometry>
          <mesh filename="package://meshes/schunk_right/f32.dae" />
        </geometry>
      </collision>
    </link>
    <link name="Rring_4">
      <visual>
        <geometry>
          <mesh filename="package://meshes/schunk_right/f33.dae" />
        </geometry>
      </visual>
      <collision>
        <geometry>
          <mesh filename="package://meshes/schunk_right/f33.dae" />
        </geometry>
      </collision>
    </link>

  <!-- PINKY FINGER LINKS -->
    <link name="Rvirtual_pinky_1">
      <visual>
        <origin xyz="0 0 -0.01321" />
        <geometry>
          <mesh filename="package://meshes/schunk_right/f40.dae" />
        </geometry>
      </visual>
      <collision>
        <origin xyz="0 0 -0.01321" />
        <geometry>
          <mesh filename="package://meshes/schunk_right/f40.dae" />
        </geometry>
      </collision>
    </link>
    <link name="Rpinky_2">
      <visual>
        <geometry>
          <mesh filename="package://meshes/schunk_right/f41.dae" />
        </geometry>
      </visual>
      <collision>
        <geometry>
          <mesh filename="package://meshes/schunk_right/f41.dae" />
        </geometry>
      </collision>
    </link>
    <link name="Rpinky_3">
      <visual>
        <geometry>
          <mesh filename="package://meshes/schunk_right/f42.dae" />
        </geometry>
      </visual>
      <collision>
        <geometry>
          <mesh filename="package://meshes/schunk_right/f42.dae" />
        </geometry>
      </collision>
    </link>
    <link name="Rpinky_4">
      <visual>
        <geometry>
          <mesh filename="package://meshes/schunk_right/f43.dae" />
        </geometry>
      </visual>
      <collision>
        <geometry>
          <mesh filename="package://meshes/schunk_right/f43.dae" />
        </geometry>
      </collision>
    </link>

  <!-- BASE_LINE JOINTS -->
    <!-- JOINT NOT FOR BASE_LINE. BUT WRITTEN DOWN HERE FOR BETTER UX -->
    <joint name="Rf1" type="fixed">
      <parent link="Re1" />
      <child link="Rd" />
      <origin xyz="0 0 0" rpy="0 0 0" />
    </joint>

    <joint name="Rf2" type="fixed">
      <parent link="Rd" />
      <child link="Rh" />
      <origin xyz="0 0 0" rpy="0 0 0" />
    </joint>


    <joint name="Rf3" type="fixed">
      <parent link="Rh" />
      <child link="Rd2" />
      <origin xyz="0 0 0" rpy="0 0 0" />
    </joint>

    <joint name="Rf4" type="fixed">
      <parent link="right_hand_base" />
      <child link="Re1" />
      <origin xyz="0 -0.01313 0" rpy="0 0 0" />
    </joint>

    <joint name="Rf5" type="fixed">
      <parent link="Re2" />
      <child link="Re3" />
      <origin xyz="0 -0.0060 0" rpy="0 0 0" />
    </joint>

    <joint name="Rf6" type="fixed">
      <parent link="Re3" />
      <child link="Re" />
      <origin xyz="0 0 0" rpy="0 0 0" />
    </joint>

    <joint name="Rf7" type="fixed">
      <parent link="Re" />
      <child link="Re4" />
      <origin xyz="0 0 0" rpy="0 0 0" />
    </joint>

    <joint name="Rf8" type="fixed">
      <parent link="Re" />
      <child link="Re5" />
      <origin xyz="0 0 0" rpy="0 0 0" />
    </joint>


  <!-- HAND JOINT -->
    <joint name="RPart_Hand" type="revolute">
      <parent link="Re1" />
      <child link="Re2" />
      <limit effort="1000.0" lower="0.0" upper="0.98786" velocity="1" />
      <origin xyz="0.01840 0.006 0.0375" rpy="0 0 0" />
      <axis xyz="0 0 1" />
      <mimic joint="RThumb_Opposition" multiplier="1" offset="0" />
    </joint>


  <!-- THUMB JOINTS -->
    <joint name="RThumb_Opposition" type="revolute">
      <parent link="Re1" />
      <child link="Rthumb_1" />
      <limit effort="1000.0" lower="0.0" upper="0.9879" velocity="1" />
      <origin xyz="-0.01690 0.02626 0" rpy="0 0.2618 1.571" />
      <axis xyz="0 0 -1" />
    </joint>

    <joint name="RThumb_Helper" type="fixed">
      <parent link="Rthumb_1" />
      <child link="Rthumb_virtual_2" />
      <origin xyz="0 0 0.04596" rpy="0 -1.5707 3.1416" />
    </joint>
    
    <joint name="RThumb_Flexion" type="revolute">
      <parent link="Rthumb_virtual_2" />
      <child link="Rthumb_3" />
      <limit effort="1000.0" lower="0.0" upper="0.9704" velocity="1" />
      <origin xyz="0 0 0" rpy="0 0 -0.9704" />
      <axis xyz="0 0 1" />
    </joint>

    <joint name="RThumb_3" type="revolute">
      <parent link="Rthumb_3" />
      <child link="Rthumb_4" />
      <limit effort="1000.0" lower="0.0" upper="0.98506" velocity="1" />
      <origin xyz="0.0485 0 0" rpy="0 0 0" />
      <axis xyz="0 0 1" />
      <mimic joint="RThumb_Flexion" multiplier="1.01511" offset="0" />
    </joint>

    <joint name="RThumb_4" type="revolute">
      <parent link="Rthumb_4" />
      <child link="Rthumb_5" />
      <limit effort="1000.0" lower="0.0" upper="1.406" velocity="1" />
      <origin xyz="0.030 0 0" rpy="0 0 0" />
      <axis xyz="0 0 1" />
      <mimic joint="RThumb_Flexion" multiplier="1.44889" offset="0" />
    </joint>

  <!-- INDEX FINGER JOINTS -->
    <joint name="RIndex_Spread" type="revolute">
      <parent link="Rd2" />
      <child link="Rvirtual_index_1" />
      <limit effort="1000.0" lower="0.0" upper="0.28833" velocity="1" />
      <origin xyz="-0.025 0 0.110" rpy="0 -1.5707 1.5707" />
      <axis xyz="0 0 1" />
      <mimic joint="RPinky_Spread" multiplier="0.5" offset="0" />
    </joint>

    <joint name="RIndex_Proximal" type="revolute">
      <parent link="Rvirtual_index_1" />
      <child link="Rindex_2" />
      <limit effort="1000.0" lower="0.0" upper="0.79849" velocity="1" />
      <origin xyz="0 0 0" rpy="-1.5707 0 0" />
      <axis xyz="0 0 1" />
    </joint>

    <joint name="RIndex_3" type="revolute">
      <parent link="Rindex_2" />
      <child link="Rindex_3" />
      <limit effort="1000.0" lower="0" upper="1.334" velocity="1" />
      <origin xyz="0.04804 0 0" rpy="0 0 0" />
      <axis xyz="0 0 1" />
    </joint>

    <joint name="RIndex_4" type="revolute">
      <parent link="Rindex_3" />
      <child link="Rindex_4" />
      <limit effort="1000.0" lower="0" upper="1.394" velocity="1" />
      <origin xyz="0.026 0 0" rpy="0 0 0" />
      <axis xyz="0 0 1" />
      <mimic joint="RIndex_3" multiplier="1.0450" offset="0" />
    </joint>

  <!-- MIDDLE FINGER JOINTS -->
    <joint name="RMiddle_Spread_Dummy" type="fixed">
      <parent link="Rd" />
      <child link="Rvirtual_middle_1" />
      <origin xyz="0 0 0.110" rpy="0 -1.5707 1.5707" />
    </joint>

    <joint name="RMiddle_Proximal" type="revolute">
      <parent link="Rvirtual_middle_1" />
      <child link="Rmiddle_2" />
      <limit effort="1000.0" lower="0.0" upper="0.79849" velocity="1" />
      <origin xyz="0 0 0" rpy="-1.5707 0 0" />
      <axis xyz="0 0 1" />
    </joint>

    <joint name="RMiddle_3" type="revolute">
      <parent link="Rmiddle_2" />
      <child link="Rmiddle_3" />
      <limit effort="1000.0" lower="0" upper="1.334" velocity="1" />
      <origin xyz="0.05004 0 0" rpy="0 0 0" />
      <axis xyz="0 0 1" />
    </joint>

    <joint name="RMiddle_4" type="revolute">
      <parent link="Rmiddle_3" />
      <child link="Rmiddle_4" />
      <limit effort="1000.0" lower="0" upper="1.334" velocity="1" />
      <origin xyz="0.032 0 0" rpy="0 0 0" />
      <axis xyz="0 0 1" />
      <mimic joint="RMiddle_3" multiplier="1.0454" offset="0" />
    </joint>


  <!-- RING FINGER JOINTS -->
    <joint name="RRing_Spread" type="revolute">
      <parent link="Re5" />
      <child link="Rvirtual_ring_1" />
      <limit effort="1000.0" lower="0.0" upper="0.28833" velocity="1" />
      <origin xyz="0.003855 0 0.0655" rpy="-1.5707 -1.5707 0" />
      <axis xyz="0 0 1" />
      <mimic joint="RPinky_Spread" multiplier="0.5" offset="0" />
    </joint>

    <joint name="RRing_Proximal" type="revolute">
      <parent link="Rvirtual_ring_1" />
      <child link="Rring_2" />
      <limit effort="1000.0" lower="0.0" upper="0.98175" velocity="1" />
      <origin xyz="0 0 0" rpy="1.5707 0 0" />
      <axis xyz="0 0 1" />
    </joint>

    <joint name="RRing_3" type="revolute">
      <parent link="Rring_2" />
      <child link="Rring_3" />
      <limit effort="1000.0" lower="0" upper="1.334" velocity="1" />
      <origin xyz="0.05004 0 0" rpy="0 0 0" />
      <axis xyz="0 0 1" />
      <mimic joint="RRing_Proximal" multiplier="1.3588" offset="0" />
    </joint>

    <joint name="RRing_4" type="revolute">
      <parent link="Rring_3" />
      <child link="Rring_4" />
      <limit effort="1000.0" lower="0" upper="1.395" velocity="1" />
      <origin xyz="0.032 0 0" rpy="0 0 0" />
      <axis xyz="0 0 1" />
      <mimic joint="RRing_Proximal" multiplier="1.42093" offset="0" />
    </joint>


  <!-- PINKY JOINTS -->
    <joint name="RPinky_Spread" type="revolute">
      <parent link="Re4" />
      <child link="Rvirtual_pinky_1" />
      <limit effort="1000.0" lower="0.0" upper="0.5829" velocity="1" />
      <origin xyz="0.025355 0 0.056" rpy="-1.5707 -1.5707 0" />
      <axis xyz="0 0 1" />
    </joint>

    <joint name="RPinky_Proximal" type="revolute">
      <parent link="Rvirtual_pinky_1" />
      <child link="Rpinky_2" />
      <limit effort="1000.0" lower="0.0" upper="0.98175" velocity="1" />
      <origin xyz="0 0 0" rpy="1.5707 0 0" />
      <axis xyz="0 0 1" />
    </joint>

    <joint name="RPinky_3" type="revolute">
      <parent link="Rpinky_2" />
      <child link="Rpinky_3" />
      <limit effort="1000.0" lower="0" upper="1.334" velocity="1" />
      <origin xyz="0.04454 0 0" rpy="0 0 0" />
      <axis xyz="0 0 1" />
      <mimic joint="RPinky_Proximal" multiplier="1.35880" offset="0" />
    </joint>

    <joint name="RPinky_4" type="revolute">
      <parent link="Rpinky_3" />
      <child link="Rpinky_4" />
      <limit effort="1000.0" lower="0" upper="1.3971" velocity="1" />
      <origin xyz="0.022 0 0" rpy="0 0 0" />
      <axis xyz="0 0 1" />
      <mimic joint="RPinky_Proximal" multiplier="1.42307" offset="0" />
    </joint>

</robot>
