<?xml version="1.0"?>
<robot name="left_schunk_hand">
    <link name="left_hand_base">
      <visual>
        <origin xyz="0 0 -0.032" rpy="0 0 0" />
        <geometry>
          <mesh filename="package://meshes/schunk_left/base10.stl" />
        </geometry>
      </visual>
      <collision>
        <origin xyz="0 0 -0.032" rpy="0 0 0" />
        <geometry>
          <mesh filename="package://meshes/schunk_left/base10.stl" />
        </geometry>
      </collision>
    </link>

    <link name="Ld">
      <!-- <visual> -->
      <!--      <geometry> -->
      <!--        <cylinder length="0.110" radius="${cyl_radius}" /> -->
      <!--      </geometry> -->
      <!--      <material name="${name}_green" /> -->
      <!-- </visual> -->
    </link>

    <link name="Lh">
      <!-- <visual> -->
      <!--      <origin rpy="0 1.571 0" xyz="${side*(-0.0125)} 0 0.0825" /> -->
      <!--      <geometry> -->
      <!--        <cylinder length="0.025" radius="${cyl_radius}" /> -->
      <!--      </geometry> -->
      <!--      <material name="${name}_green" /> -->
      <!-- </visual> -->
    </link>

    <link name="Ld2">
      <!-- <visual> -->
      <!--      <origin rpy="0 0 0" xyz="${side*(-0.025)} 0 0.09625" /> -->
      <!--      <geometry> -->
      <!--        <cylinder length="0.0275" radius="${cyl_radius}" /> -->
      <!--      </geometry> -->
      <!--      <material name="${name}_green" /> -->
      <!-- </visual> -->
    </link>

    <link name="Le">
    </link>

    <link name="Le1">
      <visual>
        <origin rpy="0 0 0" xyz="0 0.01313 0" />
        <geometry>
          <mesh scale="-1 1 1" filename="package://meshes/schunk_left/h10.stl" />
        </geometry>
      </visual>
      <collision>
        <origin rpy="0 0 0" xyz="0 0.01313 0" />
        <geometry>
          <mesh scale="-1 1 1" filename="package://meshes/schunk_left/h10.stl" />
        </geometry>
      </collision>
    </link>

    <link name="Le2">
      <visual>
        <origin xyz="0.0007 0 -0.01002" />
        <geometry>
          <mesh scale="-1 1 1" filename="package://meshes/schunk_left/h11.stl" />
        </geometry>
      </visual>
      <collision>
        <origin xyz="0.0007 0 -0.01002" />
        <geometry>
          <mesh scale="-1 1 1" filename="package://meshes/schunk_left/h11.stl" />
        </geometry>
      </collision>
    </link>

    <!-- LENGTH NOT FOUND IN DATASHEET! GUESSED!!! -->
    <link name="Le3">
      <!-- <visual> -->
      <!--      <origin rpy="0 0 0" xyz="${side*(0.0175)} 0 0.015" /> -->
      <!--      <geometry> -->
      <!--        <cylinder length="0.03" radius="${cyl_radius}" /> -->
      <!--      </geometry> -->
      <!--      <material name="green" /> -->
      <!-- </visual> -->
    </link>

    <!-- LENGTH NOT FOUND IN DATASHEET! GUESSED, BUT POSITION CALCULATED: E4 = D-G-F!!! -->
    <link name="Le4">
      <!-- <visual> -->
      <!--      <origin rpy="0 0 0" xyz="${side*(0.02825)} 0 0.043" /> -->
      <!--      <geometry> -->
      <!--        <cylinder length="0.026" radius="${cyl_radius}" /> -->
      <!--      </geometry> -->
      <!--      <material name="green" /> -->
      <!-- </visual> -->
    </link>

    <!-- LENGTH NOT FOUND IN DATASHEET! GUESSED, BUT POSITION CALCULATED: E5 = D-G!!! -->
    <link name="Le5">
      <!-- <visual> -->
      <!--      <origin rpy="0 0 0" xyz="${side*(0.00675)} 0 0.04775" /> -->
      <!--      <geometry> -->
      <!--        <cylinder length="0.0355" radius="${cyl_radius}" /> -->
      <!--      </geometry> -->
      <!--      <material name="green" /> -->
      <!-- </visual> -->
    </link>

  <!-- THUMB LINKS -->
    <link name="Lthumb_1">
      <visual>
        <origin xyz="0 0 0.02442" />
        <geometry>
          <mesh scale="1 -1 1" filename="package://meshes/schunk_left/d10.stl" />
        </geometry>
      </visual>
      <collision>
        <origin xyz="0 0 0.02442" />
        <geometry>
          <mesh scale="1 -1 1" filename="package://meshes/schunk_left/d10.stl" />
        </geometry>
      </collision>
    </link>

    <link name="Lthumb_virtual_2">
    </link>

    <link name="Lthumb_3">
      <visual>
        <geometry>
          <mesh scale="1 -1 -1" filename="package://meshes/schunk_left/d11.stl" />
        </geometry>
      </visual>
      <collision>
        <geometry>
          <mesh scale="1 -1 -1" filename="package://meshes/schunk_left/d11.stl" />
        </geometry>
      </collision>
    </link>

    <link name="Lthumb_4">
      <visual>
        <geometry>
          <mesh scale="1 -1 -1" filename="package://meshes/schunk_left/d12.stl" />
        </geometry>
      </visual>
      <collision>
        <geometry>
          <mesh scale="1 -1 -1" filename="package://meshes/schunk_left/d12.stl" />
        </geometry>
      </collision>
    </link>

    <link name="Lthumb_5">
      <visual>
        <geometry>
          <mesh scale="1 -1 -1" filename="package://meshes/schunk_left/d13.stl" />
        </geometry>
      </visual>
      <collision>
        <geometry>
          <mesh scale="1 -1 -1" filename="package://meshes/schunk_left/d13.stl" />
        </geometry>
      </collision>
    </link>


  <!-- INDEX FINGER LINKS -->
    <link name="Lvirtual_index_1">
      <visual>
        <origin xyz="0 0 0.01321" />
        <geometry>
          <mesh filename="package://meshes/schunk_left/f10.stl" />
        </geometry>
      </visual>
      <collision>
        <origin xyz="0 0 0.01321" />
        <geometry>
          <mesh filename="package://meshes/schunk_left/f10.stl" />
        </geometry>
      </collision>
    </link>

    <link name="Lindex_2">
      <visual>
        <geometry>
          <mesh filename="package://meshes/schunk_left/f11.stl" />
        </geometry>
      </visual>
      <collision>
        <geometry>
          <mesh filename="package://meshes/schunk_left/f11.stl" />
        </geometry>
      </collision>
    </link>

    <link name="Lindex_3">
      <visual>
        <geometry>
          <mesh filename="package://meshes/schunk_left/f12.stl" />
        </geometry>
      </visual>
      <collision>
        <geometry>
          <mesh filename="package://meshes/schunk_left/f12.stl" />
        </geometry>
      </collision>
    </link>

    <link name="Lindex_4">
      <visual>
        <geometry>
          <mesh filename="package://meshes/schunk_left/f13.stl" />
        </geometry>
      </visual>
      <collision>
        <geometry>
          <mesh filename="package://meshes/schunk_left/f13.stl" />
        </geometry>
      </collision>
    </link>

  <!-- MIDDLE FINGER LINKS -->
    <link name="Lvirtual_middle_1">
      <visual>
        <origin xyz="0 0 0.01321" />
        <geometry>
          <mesh filename="package://meshes/schunk_left/f20.stl" />
        </geometry>
      </visual>
      <collision>
        <origin xyz="0 0 0.01321" />
        <geometry>
          <mesh filename="package://meshes/schunk_left/f20.stl" />
        </geometry>
      </collision>
    </link>

    <link name="Lmiddle_2">
      <visual>
        <geometry>
          <mesh filename="package://meshes/schunk_left/f21.stl" />
        </geometry>
      </visual>
      <collision>
        <geometry>
          <mesh filename="package://meshes/schunk_left/f21.stl" />
        </geometry>
      </collision>
    </link>

    <link name="Lmiddle_3">
      <visual>
        <geometry>
          <mesh filename="package://meshes/schunk_left/f22.stl" />
        </geometry>
      </visual>
      <collision>
        <geometry>
          <mesh filename="package://meshes/schunk_left/f22.stl" />
        </geometry>
      </collision>
    </link>

    <link name="Lmiddle_4">
      <visual>
        <geometry>
          <mesh filename="package://meshes/schunk_left/f23.stl" />
        </geometry>
      </visual>
      <collision>
        <geometry>
          <mesh filename="package://meshes/schunk_left/f23.stl" />
        </geometry>
      </collision>
    </link>


    <!-- RING FINGER LINKS -->
    <link name="Lvirtual_ring_1">
      <visual>
        <origin xyz="0 0 -0.01321" />
        <geometry>
          <mesh filename="package://meshes/schunk_left/f30.stl" />
        </geometry>
      </visual>
      <collision>
        <origin xyz="0 0 -0.01321" />
        <geometry>
          <mesh filename="package://meshes/schunk_left/f30.stl" />
        </geometry>
      </collision>
    </link>

    <link name="Lring_2">
      <visual>
        <geometry>
          <mesh filename="package://meshes/schunk_left/f31.stl" />
        </geometry>
      </visual>
      <collision>
        <geometry>
          <mesh filename="package://meshes/schunk_left/f31.stl" />
        </geometry>
      </collision>
    </link>

    <link name="Lring_3">
      <visual>
        <geometry>
          <mesh filename="package://meshes/schunk_left/f32.stl" />
        </geometry>
      </visual>
      <collision>
        <geometry>
          <mesh filename="package://meshes/schunk_left/f32.stl" />
        </geometry>
      </collision>
    </link>

    <link name="Lring_4">
      <visual>
        <geometry>
          <mesh filename="package://meshes/schunk_left/f33.stl" />
        </geometry>
      </visual>
      <collision>
        <geometry>
          <mesh filename="package://meshes/schunk_left/f33.stl" />
        </geometry>
      </collision>
    </link>

  <!-- PINKY FINGER LINKS -->
    <link name="Lvirtual_pinky_1">
      <visual>
        <origin xyz="0 0 -0.01321" />
        <geometry>
          <mesh filename="package://meshes/schunk_left/f40.stl" />
        </geometry>
      </visual>
      <collision>
        <origin xyz="0 0 -0.01321" />
        <geometry>
          <mesh filename="package://meshes/schunk_left/f40.stl" />
        </geometry>
      </collision>
    </link>

    <link name="Lpinky_2">
      <visual>
        <geometry>
          <mesh filename="package://meshes/schunk_left/f41.stl" />
        </geometry>
      </visual>
      <collision>
        <geometry>
          <mesh filename="package://meshes/schunk_left/f41.stl" />
        </geometry>
      </collision>
    </link>

    <link name="Lpinky_3">
      <visual>
        <geometry>
          <mesh filename="package://meshes/schunk_left/f42.stl" />
        </geometry>
      </visual>
      <collision>
        <geometry>
          <mesh filename="package://meshes/schunk_left/f42.stl" />
        </geometry>
      </collision>
    </link>

    <link name="Lpinky_4">
      <visual>
        <geometry>
          <mesh filename="package://meshes/schunk_left/f43.stl" />
        </geometry>
      </visual>
      <collision>
        <geometry>
          <mesh filename="package://meshes/schunk_left/f43.stl" />
        </geometry>
      </collision>
    </link>


  
  <!-- BASE_LINE JOINTS -->
    <!-- JOINT NOT FOR BASE_LINE. BUT WRITTEN DOWN HERE FOR BETTER UX -->
    <joint name="Lf1" type="fixed">
      <parent link="Le1" />
      <child link="Ld" />
      <origin xyz="0 0 0" rpy="0 0 0" />
    </joint>

    <joint name="Lf2" type="fixed">
      <parent link="Ld" />
      <child link="Lh" />
      <origin xyz="0 0 0" rpy="0 0 0" />
    </joint>


    <joint name="Lf3" type="fixed">
      <parent link="Lh" />
      <child link="Ld2" />
      <origin xyz="0 0 0" rpy="0 0 0" />
    </joint>

    <joint name="Lf4" type="fixed">
      <parent link="left_hand_base" />
      <child link="Le1" />
      <origin xyz="0 -0.01313 0" rpy="0 0 0" />
    </joint>


    <joint name="Lf5" type="fixed">
      <parent link="Le2" />
      <child link="Le3" />
      <origin xyz="0 -0.0060 0" rpy="0 0 0" />
    </joint>

    <joint name="Lf6" type="fixed">
      <parent link="Le3" />
      <child link="Le" />
      <origin xyz="0 0 0" rpy="0 0 0" />
    </joint>

    <joint name="Lf7" type="fixed">
      <parent link="Le" />
      <child link="Le4" />
      <origin xyz="0 0 0" rpy="0 0 0" />
    </joint>

    <joint name="Lf8" type="fixed">
      <parent link="Le" />
      <child link="Le5" />
      <origin xyz="0 0 0" rpy="0 0 0" />
    </joint>

  <!-- HAND JOINTS -->
    <joint name="LPart_Hand" type="revolute">
      <parent link="Le1" />
      <child link="Le2" />
      <limit effort="1000.0" lower="0.0" upper="0.98786" velocity="1" />
      <origin xyz="-0.01840 0.006 0.0375" rpy="0 0 0" />
      <axis xyz="0 0 -1" />
      <mimic joint="LThumb_Opposition" multiplier="1" offset="0" />
    </joint>

  <!-- THUMB JOINTS -->
    <joint name="LThumb_Opposition" type="revolute">
      <parent link="Le1" />
      <child link="Lthumb_1" />
      <limit effort="1000.0" lower="0.0" upper="0.9879" velocity="1" />
      <origin xyz="0.01690 0.02626 0" rpy="0 0.2618 1.571" />
      <axis xyz="0 0 1" />
    </joint>

    <joint name="LThumb_Helper" type="fixed">
      <parent link="Lthumb_1" />
      <child link="Lthumb_virtual_2" />
      <origin xyz="0 0 0.04596" rpy="0 -1.5707 3.1416" />
    </joint>

    <joint name="LThumb_Flexion" type="revolute">
      <parent link="Lthumb_virtual_2" />
      <child link="Lthumb_3" />
      <limit effort="1000.0" lower="0.0" upper="0.9704" velocity="1" />
      <origin xyz="0 0 0" rpy="0 0 0.9704" />
      <axis xyz="0 0 -1" />
    </joint>

    <joint name="LThumb_3" type="revolute">
      <parent link="Lthumb_3" />
      <child link="Lthumb_4" />
      <limit effort="1000.0" lower="0.0" upper="0.98506" velocity="1" />
      <origin xyz="0.0485 0 0" rpy="0 0 0" />
      <axis xyz="0 0 -1" />
      <mimic joint="LThumb_Flexion" multiplier="1.01511" offset="0" />
    </joint>

    <joint name="LThumb_4" type="revolute">
      <parent link="Lthumb_4" />
      <child link="Lthumb_5" />
      <limit effort="1000.0" lower="0.0" upper="1.406" velocity="1" />
      <origin xyz="0.030 0 0" rpy="0 0 0" />
      <axis xyz="0 0 -1" />
      <mimic joint="LThumb_Flexion" multiplier="1.44889" offset="0" />
    </joint>

  <!-- INDEX FINGER JOINTS -->
    <joint name="LIndex_Spread" type="revolute">
      <parent link="Ld2" />
      <child link="Lvirtual_index_1" />
      <limit effort="1000.0" lower="0.0" upper="0.28833" velocity="1" />
      <origin xyz="0.025 0 0.110" rpy="0 -1.5707 1.5707" />
      <axis xyz="0 0 -1" />
      <mimic joint="LPinky_Spread" multiplier="0.5" offset="0" />
    </joint>

    <joint name="LIndex_Proximal" type="revolute">
      <parent link="Lvirtual_index_1" />
      <child link="Lindex_2" />
      <limit effort="1000.0" lower="0.0" upper="0.79849" velocity="1" />
      <origin xyz="0 0 0" rpy="-1.5707 0 0" />
      <axis xyz="0 0 1" />
    </joint>

    <joint name="LIndex_3" type="revolute">
      <parent link="Lindex_2" />
      <child link="Lindex_3" />
      <limit effort="1000.0" lower="0" upper="1.334" velocity="1" />
      <origin xyz="0.04804 0 0" rpy="0 0 0" />
      <axis xyz="0 0 1" />
    </joint>

    <joint name="LIndex_4" type="revolute">
      <parent link="Lindex_3" />
      <child link="Lindex_4" />
      <limit effort="1000.0" lower="0" upper="1.394" velocity="1" />
      <origin xyz="0.026 0 0" rpy="0 0 0" />
      <axis xyz="0 0 1" />
      <mimic joint="LIndex_3" multiplier="1.0450" offset="0" />
    </joint>

  <!-- MIDDLE FINGER JOINTS -->
    <joint name="LMiddle_Spread_Dummy" type="fixed">
      <parent link="Ld" />
      <child link="Lvirtual_middle_1" />
      <origin xyz="0 0 0.110" rpy="0 -1.5707 1.5707" />
    </joint>

    <joint name="LMiddle_Proximal" type="revolute">
      <parent link="Lvirtual_middle_1" />
      <child link="Lmiddle_2" />
      <limit effort="1000.0" lower="0.0" upper="0.79849" velocity="1" />
      <origin xyz="0 0 0" rpy="-1.5707 0 0" />
      <axis xyz="0 0 1" />
    </joint>

    <joint name="LMiddle_3" type="revolute">
      <parent link="Lmiddle_2" />
      <child link="Lmiddle_3" />
      <limit effort="1000.0" lower="0" upper="1.334" velocity="1" />
      <origin xyz="0.05004 0 0" rpy="0 0 0" />
      <axis xyz="0 0 1" />
    </joint>

    <joint name="LMiddle_4" type="revolute">
      <parent link="Lmiddle_3" />
      <child link="Lmiddle_4" />
      <limit effort="1000.0" lower="0" upper="1.334" velocity="1" />
      <origin xyz="0.032 0 0" rpy="0 0 0" />
      <axis xyz="0 0 1" />
      <mimic joint="LMiddle_3" multiplier="1.0454" offset="0" />
    </joint>


  <!-- RING FINGER JOINTS -->
    <joint name="LRing_Spread" type="revolute">
      <parent link="Le5" />
      <child link="Lvirtual_ring_1" />
      <limit effort="1000.0" lower="0.0" upper="0.28833" velocity="1" />
      <origin xyz="-0.003855 0 0.0655" rpy="-1.5707 -1.5707 0" />
      <axis xyz="0 0 -1" />
      <mimic joint="LPinky_Spread" multiplier="0.5" offset="0" />
    </joint>

    <joint name="LRing_Proximal" type="revolute">
      <parent link="Lvirtual_ring_1" />
      <child link="Lring_2" />
      <limit effort="1000.0" lower="0.0" upper="0.98175" velocity="1" />
      <origin xyz="0 0 0" rpy="1.5707 0 0" />
      <axis xyz="0 0 1" />
    </joint>

    <joint name="LRing_3" type="revolute">
      <parent link="Lring_2" />
      <child link="Lring_3" />
      <limit effort="1000.0" lower="0" upper="1.334" velocity="1" />
      <origin xyz="0.05004 0 0" rpy="0 0 0" />
      <axis xyz="0 0 1" />
      <mimic joint="LRing_Proximal" multiplier="1.3588" offset="0" />
    </joint>

    <joint name="LRing_4" type="revolute">
      <parent link="Lring_3" />
      <child link="Lring_4" />
      <limit effort="1000.0" lower="0" upper="1.395" velocity="1" />
      <origin xyz="0.032 0 0" rpy="0 0 0" />
      <axis xyz="0 0 1" />
      <mimic joint="LRing_Proximal" multiplier="1.42093" offset="0" />
    </joint>


  <!-- PINKY JOINTS -->
    <joint name="LPinky_Spread" type="revolute">
      <parent link="Le4" />
      <child link="Lvirtual_pinky_1" />
      <limit effort="1000.0" lower="0.0" upper="0.5829" velocity="1" />
      <origin xyz="-0.025355 0 0.056" rpy="-1.5707 -1.5707 0" />
      <axis xyz="0 0 -1" />
    </joint>

    <joint name="LPinky_Proximal" type="revolute">
      <parent link="Lvirtual_pinky_1" />
      <child link="Lpinky_2" />
      <limit effort="1000.0" lower="0.0" upper="0.98175" velocity="1" />
      <origin xyz="0 0 0" rpy="1.5707 0 0" />
      <axis xyz="0 0 1" />
    </joint>

    <joint name="LPinky_3" type="revolute">
      <parent link="Lpinky_2" />
      <child link="Lpinky_3" />
      <limit effort="1000.0" lower="0" upper="1.334" velocity="1" />
      <origin xyz="0.04454 0 0" rpy="0 0 0" />
      <axis xyz="0 0 1" />
      <mimic joint="LPinky_Proximal" multiplier="1.35880" offset="0" />
    </joint>

    <joint name="LPinky_4" type="revolute">
      <parent link="Lpinky_3" />
      <child link="Lpinky_4" />
      <limit effort="1000.0" lower="0" upper="1.3971" velocity="1" />
      <origin xyz="0.022 0 0" rpy="0 0 0" />
      <axis xyz="0 0 1" />
      <mimic joint="LPinky_Proximal" multiplier="1.42307" offset="0" />
    </joint>


</robot>
