<mujoco model="yumi">
  <compiler angle="radian" autolimits="true"/>
  <size/>
  <default/>
  <asset>
    <mesh name="body" file="meshes/body.stl"/>
    <mesh name="link_1" file="meshes/link_1.stl"/>
    <mesh name="link_2" file="meshes/link_2.stl"/>
    <mesh name="link_3" file="meshes/link_3.stl"/>
    <mesh name="link_4" file="meshes/link_4.stl"/>
    <mesh name="link_5" file="meshes/link_5.stl"/>
    <mesh name="link_6" file="meshes/link_6.stl"/>
    <mesh name="link_7" file="meshes/link_7.stl"/>

    <mesh name="link111" file="meshes/inspire_left/link111.STL"/>
    <mesh name="link1" file="meshes/inspire_left/link1.STL"/>
    <mesh name="link11" file="meshes/inspire_left/link11.STL"/>
    <mesh name="link2" file="meshes/inspire_left/link2.STL"/>
    <mesh name="link22" file="meshes/inspire_left/link22.STL"/>
    <mesh name="link3" file="meshes/inspire_left/link3.STL"/>
    <mesh name="link33" file="meshes/inspire_left/link33.STL"/>
    <mesh name="link4" file="meshes/inspire_left/link4.STL"/>
    <mesh name="link44" file="meshes/inspire_left/link44.STL"/>
    <mesh name="link5" file="meshes/inspire_left/link5.STL"/>
    <mesh name="link51" file="meshes/inspire_left/link51.STL"/>
    <mesh name="link52" file="meshes/inspire_left/link52.STL"/>
    <mesh name="link53" file="meshes/inspire_left/link53.STL"/>

    <mesh name="Link111" file="meshes/inspire_right/Link111.STL"/>
    <mesh name="Link1" file="meshes/inspire_right/Link1.STL"/>
    <mesh name="Link11" file="meshes/inspire_right/Link11.STL"/>
    <mesh name="Link2" file="meshes/inspire_right/Link2.STL"/>
    <mesh name="Link22" file="meshes/inspire_right/Link22.STL"/>
    <mesh name="Link3" file="meshes/inspire_right/Link3.STL"/>
    <mesh name="Link33" file="meshes/inspire_right/Link33.STL"/>
    <mesh name="Link4" file="meshes/inspire_right/Link4.STL"/>
    <mesh name="Link44" file="meshes/inspire_right/Link44.STL"/>
    <mesh name="Link5" file="meshes/inspire_right/Link5.STL"/>
    <mesh name="Link51" file="meshes/inspire_right/Link51.STL"/>
    <mesh name="Link52" file="meshes/inspire_right/Link52.STL"/>
    <mesh name="Link53" file="meshes/inspire_right/Link53.STL"/>
  </asset>
  <worldbody>
    <geom pos="0 0 0.1" type="mesh" mesh="body"/>
    <body name="yumi_link_1_r" pos="0.05355 -0.0725 0.51492" quat="0.00739873 -0.317362 0.40541 -0.857245">
      <inertial pos="0 -0.03 0.12" mass="2" diaginertia="0.1 0.1 0.1"/>
      <joint name="yumi_joint_1_r" pos="0 0 0" axis="0 0 1" range="-2.94088 2.94088" damping="0.5"/>
      <geom type="mesh" mesh="link_1"/>
      <body name="yumi_link_2_r" pos="0.03 0 0.1" quat="0.707107 0.707107 0 0">
        <inertial pos="0 0 0" mass="2" diaginertia="0.1 0.1 0.1"/>
        <joint name="yumi_joint_2_r" pos="0 0 0" axis="0 0 1" range="-2.50455 0.759218" damping="0.5"/>
        <geom type="mesh" mesh="link_2"/>
        <body name="yumi_link_3_r" pos="-0.03 0.17283 0" quat="0.707107 -0.707107 0 0">
          <inertial pos="0 0 0" mass="2" diaginertia="0.1 0.1 0.1"/>
          <joint name="yumi_joint_7_r" pos="0 0 0" axis="0 0 1" range="-2.94088 2.94088" damping="0.5"/>
          <geom type="mesh" mesh="link_3"/>
          <body name="yumi_link_4_r" pos="-0.04188 0 0.07873" quat="0.5 0.5 -0.5 0.5">
            <inertial pos="0 0 0" mass="2" diaginertia="0.1 0.1 0.1"/>
            <joint name="yumi_joint_3_r" pos="0 0 0" axis="0 0 1" range="-2.15548 1.39626" damping="0.5"/>
            <geom type="mesh" mesh="link_4"/>
            <body name="yumi_link_5_r" pos="0.0405 0.16461 0" quat="0.707107 -0.707107 0 0">
              <inertial pos="0 0 0" mass="2" diaginertia="0.1 0.1 0.1"/>
              <joint name="yumi_joint_4_r" pos="0 0 0" axis="0 0 1" range="-5.06145 5.06145" damping="0.5"/>
              <geom type="mesh" mesh="link_5"/>
              <body name="yumi_link_6_r" pos="-0.027 0 0.10039" quat="0.707107 0.707107 0 0">
                <inertial pos="0 0 0" mass="2" diaginertia="0.1 0.1 0.1"/>
                <joint name="yumi_joint_5_r" pos="0 0 0" axis="0 0 1" range="-1.53589 2.40855" damping="0.5"/>
                <geom type="mesh" mesh="link_6"/>
                <body name="yumi_link_7_r" pos="0.027 0.029 0" quat="0.707107 -0.707107 0 0">
                  <inertial pos="-0.0001332 0.0004269 0.00699156" quat="0.999254 -0.0291019 -0.00561524 0.0247625" mass="2.22622" diaginertia="0.101325 0.101224 0.100161"/>
                  <joint name="yumi_joint_6_r" pos="0 0 0" axis="0 0 1" range="-3.9968 3.9968" damping="0.5"/>
                  <geom type="mesh" mesh="link_7"/>
                  <geom pos="0.00849833 -0.0180008 0.0404" quat="-0.499929 0.500023 0.499977 0.500071" type="mesh" rgba="0.827451 0.839216 0.827451 1" mesh="Link111"/>
                  <body name="Link1" pos="0.00073495 -0.0220165 0.122649" quat="-0.461144 0.461246 0.535959 0.536047">
                    <inertial pos="0.010773 0.00213782 -1.34009e-07" quat="-0.0352808 0.706222 0.0352803 0.706231" mass="0.00330621" diaginertia="5.55164e-07 5.3418e-07 1.52042e-07"/>
                    <joint name="Link1" pos="0 0 0" axis="0 0 1" range="-1.6 0"/>
                    <geom type="mesh" rgba="0.792157 0.819608 0.933333 1" mesh="Link1"/>
                    <body name="Link11" pos="0.032132 0 0" quat="0.993665 -2.59237e-10 -2.93171e-11 -0.112382">
                      <inertial pos="0.0190179 0.00563448 1.90796e-08" quat="-0.0191371 0.706849 0.0191371 0.706847" mass="0.00453367" diaginertia="7.68831e-07 7.60213e-07 8.37164e-08"/>
                      <joint name="Link11" pos="0 0 0" axis="0 0 1" range="-1.7 0"/>
                      <geom type="mesh" rgba="1 1 1 1" mesh="Link11"/>
                    </body>
                  </body>
                  <body name="Link2" pos="0.000738632 -0.00269432 0.122338" quat="-0.449896 0.465986 0.548002 0.529286">
                    <inertial pos="0.010773 0.00213784 -1.14076e-07" quat="-0.0352805 0.706222 0.0352801 0.70623" mass="0.00330622" diaginertia="5.55164e-07 5.3418e-07 1.52042e-07"/>
                    <joint name="Link2" pos="0 0 0" axis="0 0 1" range="-1.6 0"/>
                    <geom type="mesh" rgba="0.792157 0.819608 0.933333 1" mesh="Link2"/>
                    <body name="Link22" pos="0.032132 0 0" quat="0.993629 -2.5923e-10 -2.94021e-11 -0.1127">
                      <inertial pos="0.0190179 0.00563448 1.97664e-08" quat="-0.0191374 0.706849 0.0191374 0.706847" mass="0.00453367" diaginertia="7.68832e-07 7.60214e-07 8.37163e-08"/>
                      <joint name="Link22" pos="0 0 0" axis="0 0 1" range="-1.7 0"/>
                      <geom type="mesh" rgba="1 1 1 1" mesh="Link22"/>
                    </body>
                  </body>
                  <body name="Link3" pos="0.000742373 0.0165057 0.121164" quat="-0.448322 0.489367 0.551451 0.5054">
                    <inertial pos="0.0107731 0.00213783 -8.57329e-08" quat="-0.0352808 0.706223 0.0352805 0.70623" mass="0.00330615" diaginertia="5.5516e-07 5.34175e-07 1.5204e-07"/>
                    <joint name="Link3" pos="0 0 0" axis="0 0 1" range="-1.6 0"/>
                    <geom type="mesh" rgba="0.792157 0.819608 0.933333 1" mesh="Link3"/>
                    <body name="Link33" pos="0.032132 0 0" quat="0.991025 -2.58552e-10 -3.48714e-11 -0.133674">
                      <inertial pos="0.0190179 0.00563447 1.7005e-08" quat="-0.019137 0.706848 0.0191371 0.706847" mass="0.00453367" diaginertia="7.68831e-07 7.60213e-07 8.37164e-08"/>
                      <joint name="Link33" pos="0 0 0" axis="0 0 1" range="-1.7 0"/>
                      <geom type="mesh" rgba="1 1 1 1" mesh="Link33"/>
                    </body>
                  </body>
                  <body name="Link4" pos="0.000746195 0.0356177 0.118986" quat="-0.425023 0.489051 0.574818 0.499768">
                    <inertial pos="0.010773 0.00213783 -7.95187e-08" quat="-0.0352807 0.706223 0.0352804 0.706229" mass="0.00330621" diaginertia="5.55164e-07 5.3418e-07 1.52042e-07"/>
                    <joint name="Link4" pos="0 0 0" axis="0 0 1" range="-1.6 0"/>
                    <geom type="mesh" rgba="0.792157 0.819608 0.933333 1" mesh="Link4"/>
                    <body name="Link44" pos="0.032132 0 0" quat="0.992825 -2.59019e-10 -3.11971e-11 -0.119573">
                      <inertial pos="0.0155925 0.00555619 -1.21775e-07" quat="-0.0259642 0.706632 0.0257978 0.706634" mass="0.00356886" diaginertia="4.39761e-07 4.354e-07 6.47934e-08"/>
                      <joint name="Link44" pos="0 0 0" axis="0 0 1" range="-1.7 0"/>
                      <geom type="mesh" rgba="1 1 1 1" mesh="Link44"/>
                    </body>
                  </body>
                  <body name="Link5" pos="-0.0144528 -0.0249865 0.0493203" quat="-0.401373 -0.387671 0.596952 0.57642">
                    <inertial pos="-0.000668288 -0.00209321 0.00376334" quat="-0.0538454 0.628063 0.0808594 0.772075" mass="0.00487391" diaginertia="2.15394e-07 1.72318e-07 1.24984e-07"/>
                    <joint name="Link5" pos="0 0 0" axis="0 1 0" range="-1 0.3"/>
                    <geom type="mesh" rgba="0.827451 0.839216 0.827451 1" mesh="Link5"/>
                    <body name="Link51" pos="0.0065 -0.0035 0.00425" quat="-3.25194e-06 0.885313 0.464996 -1.70803e-06">
                      <inertial pos="0.0261732 0.00353702 -1.92601e-07" quat="0.0149727 0.706944 -0.0149773 0.706952" mass="0.00652729" diaginertia="2.75022e-06 2.37637e-06 8.91154e-07"/>
                      <joint name="Link51" pos="0 0 0" axis="0 0 -1" range="0 0.4"/>
                      <geom type="mesh" rgba="0.792157 0.819608 0.933333 1" mesh="Link51"/>
                      <body name="Link52" pos="0.056001 0 0" quat="0.0876338 0 0 0.996153">
                        <inertial pos="-0.00731612 -0.00552223 2.1461e-07" quat="0.124858 0.695989 -0.124855 0.696003" mass="0.00226953" diaginertia="2.99631e-07 2.94813e-07 1.56044e-07"/>
                        <joint name="Link52" pos="0 0 0" axis="0 0 1" range="-0.4 0"/>
                        <geom type="mesh" rgba="0.827451 0.839216 0.827451 1" mesh="Link52"/>
                        <body name="Link53" pos="-0.022653 0 0" quat="0.458899 0.537968 -0.458901 0.53797">
                          <inertial pos="-3.39376e-06 0.010623 0.000584861" quat="0.784036 0.620711 -0.00192012 0.00135994" mass="0.0033087" diaginertia="1.9617e-07 1.91288e-07 8.09852e-08"/>
                          <joint name="Link53" pos="0 0 0" axis="1 0 0" range="-1 0"/>
                          <geom type="mesh" rgba="0.827451 0.839216 0.827451 1" mesh="Link53"/>
                        </body>
                      </body>
                    </body>
                  </body>
                </body>
              </body>
            </body>
          </body>
        </body>
      </body>
    </body>
    <body name="yumi_link_1_l" pos="0.05355 0.0725 0.51492" quat="0.00572459 0.318236 0.404752 0.857245">
      <inertial pos="0 -0.03 0.12" mass="2" diaginertia="0.1 0.1 0.1"/>
      <joint name="yumi_joint_1_l" pos="0 0 0" axis="0 0 1" range="-2.94088 2.94088" damping="0.5"/>
      <geom type="mesh" mesh="link_1"/>
      <body name="yumi_link_2_l" pos="0.03 0 0.1" quat="0.707107 0.707107 0 0">
        <inertial pos="0 0 0" mass="2" diaginertia="0.1 0.1 0.1"/>
        <joint name="yumi_joint_2_l" pos="0 0 0" axis="0 0 1" range="-2.50455 0.759218" damping="0.5"/>
        <geom type="mesh" mesh="link_2"/>
        <body name="yumi_link_3_l" pos="-0.03 0.17283 0" quat="0.707107 -0.707107 0 0">
          <inertial pos="0 0 0" mass="2" diaginertia="0.1 0.1 0.1"/>
          <joint name="yumi_joint_7_l" pos="0 0 0" axis="0 0 1" range="-2.94088 2.94088" damping="0.5"/>
          <geom type="mesh" mesh="link_3"/>
          <body name="yumi_link_4_l" pos="-0.04188 0 0.07873" quat="0.5 0.5 -0.5 0.5">
            <inertial pos="0 0 0" mass="2" diaginertia="0.1 0.1 0.1"/>
            <joint name="yumi_joint_3_l" pos="0 0 0" axis="0 0 1" range="-2.15548 1.39626" damping="0.5"/>
            <geom type="mesh" mesh="link_4"/>
            <body name="yumi_link_5_l" pos="0.0405 0.16461 0" quat="0.707107 -0.707107 0 0">
              <inertial pos="0 0 0" mass="2" diaginertia="0.1 0.1 0.1"/>
              <joint name="yumi_joint_4_l" pos="0 0 0" axis="0 0 1" range="-5.06145 5.06145" damping="0.5"/>
              <geom type="mesh" mesh="link_5"/>
              <body name="yumi_link_6_l" pos="-0.027 0 0.10039" quat="0.707107 0.707107 0 0">
                <inertial pos="0 0 0" mass="2" diaginertia="0.1 0.1 0.1"/>
                <joint name="yumi_joint_5_l" pos="0 0 0" axis="0 0 1" range="-1.53589 2.40855" damping="0.5"/>
                <geom type="mesh" mesh="link_6"/>
                <body name="yumi_link_7_l" pos="0.027 0.029 0" quat="0.707107 -0.707107 0 0">
                  <inertial pos="-0.000132842 -0.000223411 0.00706965" quat="0.999573 0.0141906 -0.00595711 -0.0248503" mass="2.22629" diaginertia="0.101344 0.101242 0.100161"/>
                  <joint name="yumi_joint_6_l" pos="0 0 0" axis="0 0 1" range="-3.9968 3.9968" damping="0.5"/>
                  <geom type="mesh" mesh="link_7"/>
                  <geom pos="0.00850176 0.0189992 0.0404" quat="3.27579e-05 0.707105 0.707108 3.27581e-05" type="mesh" rgba="0.827451 0.839216 0.827451 1" mesh="link111"/>
                  <body name="link1" pos="0.000739432 0.0258844 0.122459" quat="-0.406499 0.420964 0.583299 0.563303">
                    <inertial pos="0.0107729 0.00213788 -1.04416e-07" quat="-0.0352803 0.706223 0.03528 0.706229" mass="0.0033063" diaginertia="5.5517e-07 5.34189e-07 1.52044e-07"/>
                    <joint name="link1" pos="0 0 0" axis="0 0 1" range="-1.6 0"/>
                    <geom type="mesh" rgba="0.792157 0.819608 0.933333 1" mesh="link1"/>
                    <body name="link11" pos="0.032132 0 0" quat="0.99963 -2.60794e-10 -7.0942e-12 -0.0271916">
                      <inertial pos="0.0190179 0.00563447 1.42999e-08" quat="-0.019137 0.706849 0.0191371 0.706847" mass="0.00453367" diaginertia="7.68832e-07 7.60214e-07 8.37164e-08"/>
                      <joint name="link11" pos="0 0 0" axis="0 0 1" range="-1.7 0"/>
                      <geom type="mesh" rgba="1 1 1 1" mesh="link11"/>
                    </body>
                  </body>
                  <body name="link2" pos="0.000739469 0.00656318 0.122822" quat="-0.458017 0.458015 0.538723 0.538722">
                    <inertial pos="0.010773 0.00213784 -1.15187e-07" quat="-0.0352806 0.706222 0.0352802 0.70623" mass="0.00330622" diaginertia="5.55165e-07 5.34181e-07 1.52042e-07"/>
                    <joint name="link2" pos="0 0 0" axis="0 0 1" range="-1.6 0"/>
                    <geom type="mesh" rgba="0.792157 0.819608 0.933333 1" mesh="link2"/>
                    <body name="link22" pos="0.032132 0 0" quat="0.993629 -2.5923e-10 -2.94021e-11 -0.1127">
                      <inertial pos="0.0190179 0.00563448 1.95695e-08" quat="-0.0191374 0.706849 0.0191374 0.706847" mass="0.00453367" diaginertia="7.68832e-07 7.60214e-07 8.37163e-08"/>
                      <joint name="link22" pos="0 0 0" axis="0 0 1" range="-1.7 0"/>
                      <geom type="mesh" rgba="1 1 1 1" mesh="link22"/>
                    </body>
                  </body>
                  <body name="link3" pos="0.000739587 -0.0126658 0.122319" quat="-0.481423 0.456836 0.514912 0.542586">
                    <inertial pos="0.0107731 0.00213784 -1.44344e-07" quat="-0.0352811 0.706222 0.0352807 0.70623" mass="0.00330617" diaginertia="5.55162e-07 5.34177e-07 1.52041e-07"/>
                    <joint name="link3" pos="0 0 0" axis="0 0 1" range="-1.6 0"/>
                    <geom type="mesh" rgba="0.792157 0.819608 0.933333 1" mesh="link3"/>
                    <body name="link33" pos="0.032132 0 0" quat="0.991025 -2.58552e-10 -3.48714e-11 -0.133674">
                      <inertial pos="0.0190179 0.00563448 2.17779e-08" quat="-0.0191371 0.706849 0.0191371 0.706847" mass="0.00453367" diaginertia="7.68831e-07 7.60213e-07 8.37164e-08"/>
                      <joint name="link33" pos="0 0 0" axis="0 0 1" range="-1.7 0"/>
                      <geom type="mesh" rgba="1 1 1 1" mesh="link33"/>
                    </body>
                  </body>
                  <body name="link4" pos="0.000739797 -0.0318418 0.120809" quat="-0.464431 0.41817 0.522374 0.58014">
                    <inertial pos="0.0107729 0.00213788 -1.47686e-07" quat="-0.0352981 0.706222 0.0352631 0.70623" mass="0.0033063" diaginertia="5.55171e-07 5.3419e-07 1.52044e-07"/>
                    <joint name="link4" pos="0 0 0" axis="0 0 1" range="-1.6 0"/>
                    <geom type="mesh" rgba="0.792157 0.819608 0.933333 1" mesh="link4"/>
                    <body name="link44" pos="0.032132 0 0" quat="0.995947 -2.59834e-10 -2.34663e-11 -0.0899433">
                      <inertial pos="0.0155924 0.00555618 -1.05484e-07" quat="-0.0258816 0.70663 0.0258814 0.706636" mass="0.00356889" diaginertia="4.39764e-07 4.35403e-07 6.47939e-08"/>
                      <joint name="link44" pos="0 0 0" axis="0 0 1" range="-1.7 0"/>
                      <geom type="mesh" rgba="1 1 1 1" mesh="link44"/>
                    </body>
                  </body>
                  <body name="link5" pos="-0.0164988 0.0200629 0.0463208" quat="0.653365 0.653387 -0.2704 -0.27034">
                    <inertial pos="-0.00433166 0.000656791 -0.000486675" quat="0.0808545 0.772076 -0.0538452 0.628062" mass="0.00487394" diaginertia="2.15396e-07 1.7232e-07 1.24985e-07"/>
                    <joint name="link5" pos="0 0 0" axis="0 -1 0" range="-1 0.3"/>
                    <geom type="mesh" rgba="0.827451 0.839216 0.827451 1" mesh="link5"/>
                    <body name="link51" pos="-0.0115 -0.00075 0" quat="0.582171 0 0 0.813066">
                      <inertial pos="0.0261736 0.00353664 -7.35522e-08" quat="0.0149941 0.706941 -0.0149811 0.706955" mass="0.00652742" diaginertia="2.75022e-06 2.37618e-06 8.90996e-07"/>
                      <joint name="link51" pos="0 0 0" axis="0 0 -1" range="0 0.4"/>
                      <geom type="mesh" rgba="0.792157 0.819608 0.933333 1" mesh="link51"/>
                      <body name="link52" pos="0.056001 0 0" quat="0.0499755 0 0 -0.99875">
                        <inertial pos="-0.00731595 -0.00552217 1.31327e-07" quat="0.124777 0.695972 -0.124943 0.69602" mass="0.00226948" diaginertia="2.99629e-07 2.94812e-07 1.56042e-07"/>
                        <joint name="link52" pos="0 0 0" axis="0 0 1" range="-0.4 0"/>
                        <geom type="mesh" rgba="0.827451 0.839216 0.827451 1" mesh="link52"/>
                        <body name="link53" pos="-0.022653 0 0" quat="0.142312 0 0 0.989822">
                          <inertial pos="0.0104629 0.0019282 -3.38351e-06" quat="0.0384539 0.70576 -0.0352266 0.706529" mass="0.00330869" diaginertia="1.96169e-07 1.91288e-07 8.09849e-08"/>
                          <joint name="link53" pos="0 0 0" axis="0 0 1" range="-1 0"/>
                          <geom type="mesh" rgba="0.827451 0.839216 0.827451 1" mesh="link53"/>
                        </body>
                      </body>
                    </body>
                  </body>
                </body>
              </body>
            </body>
          </body>
        </body>
      </body>
    </body>
  </worldbody>
</mujoco>
