<mujoco model="yumi">
  <compiler angle="radian" autolimits="true"/>
  <size/>
  <default/>
  <asset>
    <mesh name="body" file="meshes/body.stl"/>
    <mesh name="link_1" file="meshes/link_1.stl"/>
    <mesh name="link_2" file="meshes/link_2.stl"/>
    <mesh name="link_3" file="meshes/link_3.stl"/>
    <mesh name="link_4" file="meshes/link_4.stl"/>
    <mesh name="link_5" file="meshes/link_5.stl"/>
    <mesh name="link_6" file="meshes/link_6.stl"/>
    <mesh name="link_7" file="meshes/link_7.stl"/>
  </asset>
  <worldbody>
    <geom pos="0 0 0.1" type="mesh" rgba="0.8 0.8 0.8 1" mesh="body"/>
    <body name="yumi_link_1_r" pos="0.05355 -0.0725 0.51492" quat="0.00739873 -0.317362 0.40541 -0.857245">
      <inertial pos="0 -0.03 0.12" mass="2" diaginertia="0.1 0.1 0.1"/>
      <joint name="yumi_joint_1_r" pos="0 0 0" axis="0 0 1" range="-2.94088 2.94088" damping="0.5"/>
      <geom type="mesh" mesh="link_1"/>
      <body name="yumi_link_2_r" pos="0.03 0 0.1" quat="0.707107 0.707107 0 0">
        <inertial pos="0 0 0" mass="2" diaginertia="0.1 0.1 0.1"/>
        <joint name="yumi_joint_2_r" pos="0 0 0" axis="0 0 1" range="-2.50455 0.759218" damping="0.5"/>
        <geom type="mesh" mesh="link_2"/>
        <body name="yumi_link_3_r" pos="-0.03 0.17283 0" quat="0.707107 -0.707107 0 0">
          <inertial pos="0 0 0" mass="2" diaginertia="0.1 0.1 0.1"/>
          <joint name="yumi_joint_7_r" pos="0 0 0" axis="0 0 1" range="-2.94088 2.94088" damping="0.5"/>
          <geom type="mesh" mesh="link_3"/>
          <body name="yumi_link_4_r" pos="-0.04188 0 0.07873" quat="0.5 0.5 -0.5 0.5">
            <inertial pos="0 0 0" mass="2" diaginertia="0.1 0.1 0.1"/>
            <joint name="yumi_joint_3_r" pos="0 0 0" axis="0 0 1" range="-2.15548 1.39626" damping="0.5"/>
            <geom type="mesh" mesh="link_4"/>
            <body name="yumi_link_5_r" pos="0.0405 0.16461 0" quat="0.707107 -0.707107 0 0">
              <inertial pos="0 0 0" mass="2" diaginertia="0.1 0.1 0.1"/>
              <joint name="yumi_joint_4_r" pos="0 0 0" axis="0 0 1" range="-5.06145 5.06145" damping="0.5"/>
              <geom type="mesh" mesh="link_5"/>
              <body name="yumi_link_6_r" pos="-0.027 0 0.10039" quat="0.707107 0.707107 0 0">
                <inertial pos="0 0 0" mass="2" diaginertia="0.1 0.1 0.1"/>
                <joint name="yumi_joint_5_r" pos="0 0 0" axis="0 0 1" range="-1.53589 2.40855" damping="0.5"/>
                <geom type="mesh" mesh="link_6"/>
                <body name="yumi_link_7_r" pos="0.027 0.029 0" quat="0.707107 -0.707107 0 0">
                  <inertial pos="0 0 0" mass="2" diaginertia="0.1 0.1 0.1"/>
                  <joint name="yumi_joint_6_r" pos="0 0 0" axis="0 0 1" range="-3.9968 3.9968" damping="0.5"/>
                  <geom type="mesh" mesh="link_7"/>
                </body>
              </body>
            </body>
          </body>
        </body>
      </body>
    </body>
    <body name="yumi_link_1_l" pos="0.05355 0.0725 0.51492" quat="0.00572459 0.318236 0.404752 0.857245">
      <inertial pos="0 -0.03 0.12" mass="2" diaginertia="0.1 0.1 0.1"/>
      <joint name="yumi_joint_1_l" pos="0 0 0" axis="0 0 1" range="-2.94088 2.94088" damping="0.5"/>
      <geom type="mesh" mesh="link_1"/>
      <body name="yumi_link_2_l" pos="0.03 0 0.1" quat="0.707107 0.707107 0 0">
        <inertial pos="0 0 0" mass="2" diaginertia="0.1 0.1 0.1"/>
        <joint name="yumi_joint_2_l" pos="0 0 0" axis="0 0 1" range="-2.50455 0.759218" damping="0.5"/>
        <geom type="mesh" mesh="link_2"/>
        <body name="yumi_link_3_l" pos="-0.03 0.17283 0" quat="0.707107 -0.707107 0 0">
          <inertial pos="0 0 0" mass="2" diaginertia="0.1 0.1 0.1"/>
          <joint name="yumi_joint_7_l" pos="0 0 0" axis="0 0 1" range="-2.94088 2.94088" damping="0.5"/>
          <geom type="mesh" mesh="link_3"/>
          <body name="yumi_link_4_l" pos="-0.04188 0 0.07873" quat="0.5 0.5 -0.5 0.5">
            <inertial pos="0 0 0" mass="2" diaginertia="0.1 0.1 0.1"/>
            <joint name="yumi_joint_3_l" pos="0 0 0" axis="0 0 1" range="-2.15548 1.39626" damping="0.5"/>
            <geom type="mesh" mesh="link_4"/>
            <body name="yumi_link_5_l" pos="0.0405 0.16461 0" quat="0.707107 -0.707107 0 0">
              <inertial pos="0 0 0" mass="2" diaginertia="0.1 0.1 0.1"/>
              <joint name="yumi_joint_4_l" pos="0 0 0" axis="0 0 1" range="-5.06145 5.06145" damping="0.5"/>
              <geom type="mesh" mesh="link_5"/>
              <body name="yumi_link_6_l" pos="-0.027 0 0.10039" quat="0.707107 0.707107 0 0">
                <inertial pos="0 0 0" mass="2" diaginertia="0.1 0.1 0.1"/>
                <joint name="yumi_joint_5_l" pos="0 0 0" axis="0 0 1" range="-1.53589 2.40855" damping="0.5"/>
                <geom type="mesh" mesh="link_6"/>
                <body name="yumi_link_7_l" pos="0.027 0.029 0" quat="0.707107 -0.707107 0 0">
                  <inertial pos="0 0 0" mass="2" diaginertia="0.1 0.1 0.1"/>
                  <joint name="yumi_joint_6_l" pos="0 0 0" axis="0 0 1" range="-3.9968 3.9968" damping="0.5"/>
                  <geom type="mesh" mesh="link_7"/>
                </body>
              </body>
            </body>
          </body>
        </body>
      </body>
    </body>
  </worldbody>
</mujoco>
