<?xml version="1.0"?>
<robot name="schunk_hand">
    <link name="base_link">
      <visual>
        <origin xyz="0 0 -0.032" rpy="0 0 0" />
        <geometry>
          <mesh filename="package://meshes/base10.dae" />
        </geometry>
      </visual>
      <collision>
        <origin xyz="0 0 -0.032" rpy="0 0 0" />
        <geometry>
          <mesh filename="package://meshes/base10.dae" />
        </geometry>
      </collision>
    </link>

    <link name="d">
      <!-- <visual> -->
      <!--      <geometry> -->
      <!--        <cylinder length="0.110" radius="${cyl_radius}" /> -->
      <!--      </geometry> -->
      <!--      <material name="${name}_green" /> -->
      <!-- </visual> -->
    </link>

    <link name="h">
      <!-- <visual> -->
      <!--      <origin rpy="0 1.571 0" xyz="${side*(-0.0125)} 0 0.0825" /> -->
      <!--      <geometry> -->
      <!--        <cylinder length="0.025" radius="${cyl_radius}" /> -->
      <!--      </geometry> -->
      <!--      <material name="${name}_green" /> -->
      <!-- </visual> -->
    </link>

    <link name="d2">
      <!-- <visual> -->
      <!--      <origin rpy="0 0 0" xyz="${side*(-0.025)} 0 0.09625" /> -->
      <!--      <geometry> -->
      <!--        <cylinder length="0.0275" radius="${cyl_radius}" /> -->
      <!--      </geometry> -->
      <!--      <material name="${name}_green" /> -->
      <!-- </visual> -->
    </link>

    <link name="e">
    </link>

    <link name="e1">
      <visual>
        <origin rpy="0 0 0" xyz="0 0.01313 0" />
        <geometry>
          <mesh scale="-1 1 1" filename="package://meshes/h10.dae" />
        </geometry>
      </visual>
      <collision>
        <origin rpy="0 0 0" xyz="0 0.01313 0" />
        <geometry>
          <mesh scale="-1 1 1" filename="package://meshes/h10.dae" />
        </geometry>
      </collision>
    </link>

    <link name="e2">
      <visual>
        <origin xyz="0.0007 0 -0.01002" />
        <geometry>
          <mesh scale="-1 1 1" filename="package://meshes/h11.dae" />
        </geometry>
      </visual>
      <collision>
        <origin xyz="0.0007 0 -0.01002" />
        <geometry>
          <mesh scale="-1 1 1" filename="package://meshes/h11.dae" />
        </geometry>
      </collision>
    </link>

    <!-- LENGTH NOT FOUND IN DATASHEET! GUESSED!!! -->
    <link name="e3">
      <!-- <visual> -->
      <!--      <origin rpy="0 0 0" xyz="${side*(0.0175)} 0 0.015" /> -->
      <!--      <geometry> -->
      <!--        <cylinder length="0.03" radius="${cyl_radius}" /> -->
      <!--      </geometry> -->
      <!--      <material name="green" /> -->
      <!-- </visual> -->
    </link>

    <!-- LENGTH NOT FOUND IN DATASHEET! GUESSED, BUT POSITION CALCULATED: E4 = D-G-F!!! -->
    <link name="e4">
      <!-- <visual> -->
      <!--      <origin rpy="0 0 0" xyz="${side*(0.02825)} 0 0.043" /> -->
      <!--      <geometry> -->
      <!--        <cylinder length="0.026" radius="${cyl_radius}" /> -->
      <!--      </geometry> -->
      <!--      <material name="green" /> -->
      <!-- </visual> -->
    </link>

    <!-- LENGTH NOT FOUND IN DATASHEET! GUESSED, BUT POSITION CALCULATED: E5 = D-G!!! -->
    <link name="e5">
      <!-- <visual> -->
      <!--      <origin rpy="0 0 0" xyz="${side*(0.00675)} 0 0.04775" /> -->
      <!--      <geometry> -->
      <!--        <cylinder length="0.0355" radius="${cyl_radius}" /> -->
      <!--      </geometry> -->
      <!--      <material name="green" /> -->
      <!-- </visual> -->
    </link>

    <!-- THUMB LINKS -->
    <link name="thumb_1">
      <visual>
        <origin xyz="0 0 0.02442" />
        <geometry>
          <mesh scale="1 -1 1" filename="package://meshes/d10.dae" />
        </geometry>
      </visual>
      <collision>
        <origin xyz="0 0 0.02442" />
        <geometry>
          <mesh scale="1 -1 1" filename="package://meshes/d10.dae" />
        </geometry>
      </collision>
    </link>

    <link name="thumb_virtual_2">
    </link>

    <link name="thumb_3">
      <visual>
        <geometry>
          <mesh scale="1 -1 -1" filename="package://meshes/d11.dae" />
        </geometry>
      </visual>
      <collision>
        <geometry>
          <mesh scale="1 -1 -1" filename="package://meshes/d11.dae" />
        </geometry>
      </collision>
    </link>

    <link name="thumb_4">
      <visual>
        <geometry>
          <mesh scale="1 -1 -1" filename="package://meshes/d12.dae" />
        </geometry>
      </visual>
      <collision>
        <geometry>
          <mesh scale="1 -1 -1" filename="package://meshes/d12.dae" />
        </geometry>
      </collision>
    </link>

    <link name="thumb_5">
      <visual>
        <geometry>
          <mesh scale="1 -1 -1" filename="package://meshes/d13.dae" />
        </geometry>
      </visual>
      <collision>
        <geometry>
          <mesh scale="1 -1 -1" filename="package://meshes/d13.dae" />
        </geometry>
      </collision>
    </link>


  <!-- INDEX FINGER LINKS -->
    <link name="virtual_index_1">
      <visual>
        <origin xyz="0 0 0.01321" />
        <geometry>
          <mesh filename="package://meshes/f10.dae" />
        </geometry>
      </visual>
      <collision>
        <origin xyz="0 0 0.01321" />
        <geometry>
          <mesh filename="package://meshes/f10.dae" />
        </geometry>
      </collision>
    </link>

    <link name="index_2">
      <visual>
        <geometry>
          <mesh filename="package://meshes/f11.dae" />
        </geometry>
      </visual>
      <collision>
        <geometry>
          <mesh filename="package://meshes/f11.dae" />
        </geometry>
      </collision>
    </link>

    <link name="index_3">
      <visual>
        <geometry>
          <mesh filename="package://meshes/f12.dae" />
        </geometry>
      </visual>
      <collision>
        <geometry>
          <mesh filename="package://meshes/f12.dae" />
        </geometry>
      </collision>
    </link>

    <link name="index_4">
      <visual>
        <geometry>
          <mesh filename="package://meshes/f13.dae" />
        </geometry>
      </visual>
      <collision>
        <geometry>
          <mesh filename="package://meshes/f13.dae" />
        </geometry>
      </collision>
    </link>

  <!-- MIDDLE FINGER LINKS -->
    <link name="virtual_middle_1">
      <visual>
        <origin xyz="0 0 0.01321" />
        <geometry>
          <mesh filename="package://meshes/f20.dae" />
        </geometry>
      </visual>
      <collision>
        <origin xyz="0 0 0.01321" />
        <geometry>
          <mesh filename="package://meshes/f20.dae" />
        </geometry>
      </collision>
    </link>

    <link name="middle_2">
      <visual>
        <geometry>
          <mesh filename="package://meshes/f21.dae" />
        </geometry>
      </visual>
      <collision>
        <geometry>
          <mesh filename="package://meshes/f21.dae" />
        </geometry>
      </collision>
    </link>

    <link name="middle_3">
      <visual>
        <geometry>
          <mesh filename="package://meshes/f22.dae" />
        </geometry>
      </visual>
      <collision>
        <geometry>
          <mesh filename="package://meshes/f22.dae" />
        </geometry>
      </collision>
    </link>

    <link name="middle_4">
      <visual>
        <geometry>
          <mesh filename="package://meshes/f23.dae" />
        </geometry>
      </visual>
      <collision>
        <geometry>
          <mesh filename="package://meshes/f23.dae" />
        </geometry>
      </collision>
    </link>


    <!-- RING FINGER LINKS -->
    <link name="virtual_ring_1">
      <visual>
        <origin xyz="0 0 -0.01321" />
        <geometry>
          <mesh filename="package://meshes/f30.dae" />
        </geometry>
      </visual>
      <collision>
        <origin xyz="0 0 -0.01321" />
        <geometry>
          <mesh filename="package://meshes/f30.dae" />
        </geometry>
      </collision>
    </link>

    <link name="ring_2">
      <visual>
        <geometry>
          <mesh filename="package://meshes/f31.dae" />
        </geometry>
      </visual>
      <collision>
        <geometry>
          <mesh filename="package://meshes/f31.dae" />
        </geometry>
      </collision>
    </link>

    <link name="ring_3">
      <visual>
        <geometry>
          <mesh filename="package://meshes/f32.dae" />
        </geometry>
      </visual>
      <collision>
        <geometry>
          <mesh filename="package://meshes/f32.dae" />
        </geometry>
      </collision>
    </link>

    <link name="ring_4">
      <visual>
        <geometry>
          <mesh filename="package://meshes/f33.dae" />
        </geometry>
      </visual>
      <collision>
        <geometry>
          <mesh filename="package://meshes/f33.dae" />
        </geometry>
      </collision>
    </link>

  <!-- PINKY FINGER LINKS -->
    <link name="virtual_pinky_1">
      <visual>
        <origin xyz="0 0 -0.01321" />
        <geometry>
          <mesh filename="package://meshes/f40.dae" />
        </geometry>
      </visual>
      <collision>
        <origin xyz="0 0 -0.01321" />
        <geometry>
          <mesh filename="package://meshes/f40.dae" />
        </geometry>
      </collision>
    </link>

    <link name="pinky_2">
      <visual>
        <geometry>
          <mesh filename="package://meshes/f41.dae" />
        </geometry>
      </visual>
      <collision>
        <geometry>
          <mesh filename="package://meshes/f41.dae" />
        </geometry>
      </collision>
    </link>

    <link name="pinky_3">
      <visual>
        <geometry>
          <mesh filename="package://meshes/f42.dae" />
        </geometry>
      </visual>
      <collision>
        <geometry>
          <mesh filename="package://meshes/f42.dae" />
        </geometry>
      </collision>
    </link>

    <link name="pinky_4">
      <visual>
        <geometry>
          <mesh filename="package://meshes/f43.dae" />
        </geometry>
      </visual>
      <collision>
        <geometry>
          <mesh filename="package://meshes/f43.dae" />
        </geometry>
      </collision>
    </link>


  
  <!-- BASE_LINE JOINTS -->
    <!-- JOINT NOT FOR BASE_LINE. BUT WRITTEN DOWN HERE FOR BETTER UX -->
    <joint name="f1" type="fixed">
      <parent link="e1" />
      <child link="d" />
      <origin xyz="0 0 0" rpy="0 0 0" />
    </joint>

    <joint name="f2" type="fixed">
      <parent link="d" />
      <child link="h" />
      <origin xyz="0 0 0" rpy="0 0 0" />
    </joint>


    <joint name="f3" type="fixed">
      <parent link="h" />
      <child link="d2" />
      <origin xyz="0 0 0" rpy="0 0 0" />
    </joint>

    <joint name="f4" type="fixed">
      <parent link="base_link" />
      <child link="e1" />
      <origin xyz="0 -0.01313 0" rpy="0 0 0" />
    </joint>


    <joint name="f5" type="fixed">
      <parent link="e2" />
      <child link="e3" />
      <origin xyz="0 -0.0060 0" rpy="0 0 0" />
    </joint>

    <joint name="f6" type="fixed">
      <parent link="e3" />
      <child link="e" />
      <origin xyz="0 0 0" rpy="0 0 0" />
    </joint>

    <joint name="f7" type="fixed">
      <parent link="e" />
      <child link="e4" />
      <origin xyz="0 0 0" rpy="0 0 0" />
    </joint>

    <joint name="f8" type="fixed">
      <parent link="e" />
      <child link="e5" />
      <origin xyz="0 0 0" rpy="0 0 0" />
    </joint>

  <!-- HAND JOINTS -->
    <joint name="Part_Hand" type="revolute">
      <parent link="e1" />
      <child link="e2" />
      <limit effort="1000.0" lower="0.0" upper="0.98786" velocity="1" />
      <origin xyz="-0.01840 0.006 0.0375" rpy="0 0 0" />
      <axis xyz="0 0 -1" />
      <mimic joint="Thumb_Opposition" multiplier="1" offset="0" />
    </joint>

  <!-- THUMB JOINTS -->
    <joint name="Thumb_Opposition" type="revolute">
      <parent link="e1" />
      <child link="thumb_1" />
      <limit effort="1000.0" lower="0.0" upper="0.9879" velocity="1" />
      <origin xyz="0.01690 0.02626 0" rpy="0 0.2618 1.571" />
      <axis xyz="0 0 1" />
    </joint>

    <joint name="Thumb_Helper" type="fixed">
      <parent link="thumb_1" />
      <child link="thumb_virtual_2" />
      <origin xyz="0 0 0.04596" rpy="0 -1.5707 3.1416" />
    </joint>

    <joint name="Thumb_Flexion" type="revolute">
      <parent link="thumb_virtual_2" />
      <child link="thumb_3" />
      <limit effort="1000.0" lower="0.0" upper="0.9704" velocity="1" />
      <origin xyz="0 0 0" rpy="0 0 0.9704" />
      <axis xyz="0 0 -1" />
    </joint>

    <joint name="Thumb_3" type="revolute">
      <parent link="thumb_3" />
      <child link="thumb_4" />
      <limit effort="1000.0" lower="0.0" upper="0.98506" velocity="1" />
      <origin xyz="0.0485 0 0" rpy="0 0 0" />
      <axis xyz="0 0 -1" />
      <mimic joint="Thumb_Flexion" multiplier="1.01511" offset="0" />
    </joint>

    <joint name="Thumb_4" type="revolute">
      <parent link="thumb_4" />
      <child link="thumb_5" />
      <limit effort="1000.0" lower="0.0" upper="1.406" velocity="1" />
      <origin xyz="0.030 0 0" rpy="0 0 0" />
      <axis xyz="0 0 -1" />
      <mimic joint="Thumb_Flexion" multiplier="1.44889" offset="0" />
    </joint>

  <!-- INDEX FINGER JOINTS -->
    <joint name="Index_Spread" type="revolute">
      <parent link="d2" />
      <child link="virtual_index_1" />
      <limit effort="1000.0" lower="0.0" upper="0.28833" velocity="1" />
      <origin xyz="0.025 0 0.110" rpy="0 -1.5707 1.5707" />
      <axis xyz="0 0 -1" />
      <mimic joint="Pinky_Spread" multiplier="0.5" offset="0" />
    </joint>

    <joint name="Index_Proximal" type="revolute">
      <parent link="virtual_index_1" />
      <child link="index_2" />
      <limit effort="1000.0" lower="0.0" upper="0.79849" velocity="1" />
      <origin xyz="0 0 0" rpy="-1.5707 0 0" />
      <axis xyz="0 0 1" />
    </joint>

    <joint name="Index_3" type="revolute">
      <parent link="index_2" />
      <child link="index_3" />
      <limit effort="1000.0" lower="0" upper="1.334" velocity="1" />
      <origin xyz="0.04804 0 0" rpy="0 0 0" />
      <axis xyz="0 0 1" />
    </joint>

    <joint name="Index_4" type="revolute">
      <parent link="index_3" />
      <child link="index_4" />
      <limit effort="1000.0" lower="0" upper="1.394" velocity="1" />
      <origin xyz="0.026 0 0" rpy="0 0 0" />
      <axis xyz="0 0 1" />
      <mimic joint="Index_3" multiplier="1.0450" offset="0" />
    </joint>

  <!-- MIDDLE FINGER JOINTS -->
    <joint name="Middle_Spread_Dummy" type="fixed">
      <parent link="d" />
      <child link="virtual_middle_1" />
      <origin xyz="0 0 0.110" rpy="0 -1.5707 1.5707" />
    </joint>

    <joint name="Middle_Proximal" type="revolute">
      <parent link="virtual_middle_1" />
      <child link="middle_2" />
      <limit effort="1000.0" lower="0.0" upper="0.79849" velocity="1" />
      <origin xyz="0 0 0" rpy="-1.5707 0 0" />
      <axis xyz="0 0 1" />
    </joint>

    <joint name="Middle_3" type="revolute">
      <parent link="middle_2" />
      <child link="middle_3" />
      <limit effort="1000.0" lower="0" upper="1.334" velocity="1" />
      <origin xyz="0.05004 0 0" rpy="0 0 0" />
      <axis xyz="0 0 1" />
    </joint>

    <joint name="Middle_4" type="revolute">
      <parent link="middle_3" />
      <child link="middle_4" />
      <limit effort="1000.0" lower="0" upper="1.334" velocity="1" />
      <origin xyz="0.032 0 0" rpy="0 0 0" />
      <axis xyz="0 0 1" />
      <mimic joint="Middle_3" multiplier="1.0454" offset="0" />
    </joint>


  <!-- RING FINGER JOINTS -->
    <joint name="Ring_Spread" type="revolute">
      <parent link="e5" />
      <child link="virtual_ring_1" />
      <limit effort="1000.0" lower="0.0" upper="0.28833" velocity="1" />
      <origin xyz="-0.003855 0 0.0655" rpy="-1.5707 -1.5707 0" />
      <axis xyz="0 0 -1" />
      <mimic joint="Pinky_Spread" multiplier="0.5" offset="0" />
    </joint>

    <joint name="Ring_Proximal" type="revolute">
      <parent link="virtual_ring_1" />
      <child link="ring_2" />
      <limit effort="1000.0" lower="0.0" upper="0.98175" velocity="1" />
      <origin xyz="0 0 0" rpy="1.5707 0 0" />
      <axis xyz="0 0 1" />
    </joint>

    <joint name="Ring_3" type="revolute">
      <parent link="ring_2" />
      <child link="ring_3" />
      <limit effort="1000.0" lower="0" upper="1.334" velocity="1" />
      <origin xyz="0.05004 0 0" rpy="0 0 0" />
      <axis xyz="0 0 1" />
      <mimic joint="Ring_Proximal" multiplier="1.3588" offset="0" />
    </joint>

    <joint name="Ring_4" type="revolute">
      <parent link="ring_3" />
      <child link="ring_4" />
      <limit effort="1000.0" lower="0" upper="1.395" velocity="1" />
      <origin xyz="0.032 0 0" rpy="0 0 0" />
      <axis xyz="0 0 1" />
      <mimic joint="Ring_Proximal" multiplier="1.42093" offset="0" />
    </joint>


  <!-- PINKY JOINTS -->
    <joint name="Pinky_Spread" type="revolute">
      <parent link="e4" />
      <child link="virtual_pinky_1" />
      <limit effort="1000.0" lower="0.0" upper="0.5829" velocity="1" />
      <origin xyz="-0.025355 0 0.056" rpy="-1.5707 -1.5707 0" />
      <axis xyz="0 0 -1" />
    </joint>

    <joint name="Pinky_Proximal" type="revolute">
      <parent link="virtual_pinky_1" />
      <child link="pinky_2" />
      <limit effort="1000.0" lower="0.0" upper="0.98175" velocity="1" />
      <origin xyz="0 0 0" rpy="1.5707 0 0" />
      <axis xyz="0 0 1" />
    </joint>

    <joint name="Pinky_3" type="revolute">
      <parent link="pinky_2" />
      <child link="pinky_3" />
      <limit effort="1000.0" lower="0" upper="1.334" velocity="1" />
      <origin xyz="0.04454 0 0" rpy="0 0 0" />
      <axis xyz="0 0 1" />
      <mimic joint="Pinky_Proximal" multiplier="1.35880" offset="0" />
    </joint>

    <joint name="Pinky_4" type="revolute">
      <parent link="pinky_3" />
      <child link="pinky_4" />
      <limit effort="1000.0" lower="0" upper="1.3971" velocity="1" />
      <origin xyz="0.022 0 0" rpy="0 0 0" />
      <axis xyz="0 0 1" />
      <mimic joint="Pinky_Proximal" multiplier="1.42307" offset="0" />
    </joint>


</robot>
